[2020-04-16 19:27:40,843] {/home/alta11/virtualenv/rest_training/lib/python3.6/site-packages/flask/app.py:1892} ERROR - Exception on /user [POST]
Traceback (most recent call last):
  File "/home/alta11/virtualenv/rest_training/lib/python3.6/site-packages/sqlalchemy/engine/base.py", line 1248, in _execute_context
    cursor, statement, parameters, context
  File "/home/alta11/virtualenv/rest_training/lib/python3.6/site-packages/sqlalchemy/engine/default.py", line 590, in do_execute
    cursor.execute(statement, parameters)
  File "/home/alta11/virtualenv/rest_training/lib/python3.6/site-packages/pymysql/cursors.py", line 170, in execute
    result = self._query(query)
  File "/home/alta11/virtualenv/rest_training/lib/python3.6/site-packages/pymysql/cursors.py", line 328, in _query
    conn.query(q)
  File "/home/alta11/virtualenv/rest_training/lib/python3.6/site-packages/pymysql/connections.py", line 517, in query
    self._affected_rows = self._read_query_result(unbuffered=unbuffered)
  File "/home/alta11/virtualenv/rest_training/lib/python3.6/site-packages/pymysql/connections.py", line 732, in _read_query_result
    result.read()
  File "/home/alta11/virtualenv/rest_training/lib/python3.6/site-packages/pymysql/connections.py", line 1075, in read
    first_packet = self.connection._read_packet()
  File "/home/alta11/virtualenv/rest_training/lib/python3.6/site-packages/pymysql/connections.py", line 684, in _read_packet
    packet.check_error()
  File "/home/alta11/virtualenv/rest_training/lib/python3.6/site-packages/pymysql/protocol.py", line 220, in check_error
    err.raise_mysql_exception(self._data)
  File "/home/alta11/virtualenv/rest_training/lib/python3.6/site-packages/pymysql/err.py", line 109, in raise_mysql_exception
    raise errorclass(errno, errval)
pymysql.err.IntegrityError: (1062, "Duplicate entry 'fast' for key 'name'")

The above exception was the direct cause of the following exception:

Traceback (most recent call last):
  File "/home/alta11/virtualenv/rest_training/lib/python3.6/site-packages/flask/app.py", line 1950, in full_dispatch_request
    rv = self.dispatch_request()
  File "/home/alta11/virtualenv/rest_training/lib/python3.6/site-packages/flask/app.py", line 1936, in dispatch_request
    return self.view_functions[rule.endpoint](**req.view_args)
  File "/home/alta11/virtualenv/rest_training/lib/python3.6/site-packages/flask_restful/__init__.py", line 468, in wrapper
    resp = resource(*args, **kwargs)
  File "/home/alta11/virtualenv/rest_training/lib/python3.6/site-packages/flask/views.py", line 89, in view
    return self.dispatch_request(*args, **kwargs)
  File "/home/alta11/virtualenv/rest_training/lib/python3.6/site-packages/flask_restful/__init__.py", line 583, in dispatch_request
    resp = meth(*args, **kwargs)
  File "/home/alta11/fullstack5_alul/Restful_API/2-FlaskRouting_Controller_Blueprint/blueprints/user/resources.py", line 35, in post
    db.session.commit()
  File "/home/alta11/virtualenv/rest_training/lib/python3.6/site-packages/sqlalchemy/orm/scoping.py", line 162, in do
    return getattr(self.registry(), name)(*args, **kwargs)
  File "/home/alta11/virtualenv/rest_training/lib/python3.6/site-packages/sqlalchemy/orm/session.py", line 1036, in commit
    self.transaction.commit()
  File "/home/alta11/virtualenv/rest_training/lib/python3.6/site-packages/sqlalchemy/orm/session.py", line 503, in commit
    self._prepare_impl()
  File "/home/alta11/virtualenv/rest_training/lib/python3.6/site-packages/sqlalchemy/orm/session.py", line 482, in _prepare_impl
    self.session.flush()
  File "/home/alta11/virtualenv/rest_training/lib/python3.6/site-packages/sqlalchemy/orm/session.py", line 2496, in flush
    self._flush(objects)
  File "/home/alta11/virtualenv/rest_training/lib/python3.6/site-packages/sqlalchemy/orm/session.py", line 2637, in _flush
    transaction.rollback(_capture_exception=True)
  File "/home/alta11/virtualenv/rest_training/lib/python3.6/site-packages/sqlalchemy/util/langhelpers.py", line 69, in __exit__
    exc_value, with_traceback=exc_tb,
  File "/home/alta11/virtualenv/rest_training/lib/python3.6/site-packages/sqlalchemy/util/compat.py", line 178, in raise_
    raise exception
  File "/home/alta11/virtualenv/rest_training/lib/python3.6/site-packages/sqlalchemy/orm/session.py", line 2597, in _flush
    flush_context.execute()
  File "/home/alta11/virtualenv/rest_training/lib/python3.6/site-packages/sqlalchemy/orm/unitofwork.py", line 422, in execute
    rec.execute(self)
  File "/home/alta11/virtualenv/rest_training/lib/python3.6/site-packages/sqlalchemy/orm/unitofwork.py", line 589, in execute
    uow,
  File "/home/alta11/virtualenv/rest_training/lib/python3.6/site-packages/sqlalchemy/orm/persistence.py", line 245, in save_obj
    insert,
  File "/home/alta11/virtualenv/rest_training/lib/python3.6/site-packages/sqlalchemy/orm/persistence.py", line 1136, in _emit_insert_statements
    statement, params
  File "/home/alta11/virtualenv/rest_training/lib/python3.6/site-packages/sqlalchemy/engine/base.py", line 984, in execute
    return meth(self, multiparams, params)
  File "/home/alta11/virtualenv/rest_training/lib/python3.6/site-packages/sqlalchemy/sql/elements.py", line 293, in _execute_on_connection
    return connection._execute_clauseelement(self, multiparams, params)
  File "/home/alta11/virtualenv/rest_training/lib/python3.6/site-packages/sqlalchemy/engine/base.py", line 1103, in _execute_clauseelement
    distilled_params,
  File "/home/alta11/virtualenv/rest_training/lib/python3.6/site-packages/sqlalchemy/engine/base.py", line 1288, in _execute_context
    e, statement, parameters, cursor, context
  File "/home/alta11/virtualenv/rest_training/lib/python3.6/site-packages/sqlalchemy/engine/base.py", line 1482, in _handle_dbapi_exception
    sqlalchemy_exception, with_traceback=exc_info[2], from_=e
  File "/home/alta11/virtualenv/rest_training/lib/python3.6/site-packages/sqlalchemy/util/compat.py", line 178, in raise_
    raise exception
  File "/home/alta11/virtualenv/rest_training/lib/python3.6/site-packages/sqlalchemy/engine/base.py", line 1248, in _execute_context
    cursor, statement, parameters, context
  File "/home/alta11/virtualenv/rest_training/lib/python3.6/site-packages/sqlalchemy/engine/default.py", line 590, in do_execute
    cursor.execute(statement, parameters)
  File "/home/alta11/virtualenv/rest_training/lib/python3.6/site-packages/pymysql/cursors.py", line 170, in execute
    result = self._query(query)
  File "/home/alta11/virtualenv/rest_training/lib/python3.6/site-packages/pymysql/cursors.py", line 328, in _query
    conn.query(q)
  File "/home/alta11/virtualenv/rest_training/lib/python3.6/site-packages/pymysql/connections.py", line 517, in query
    self._affected_rows = self._read_query_result(unbuffered=unbuffered)
  File "/home/alta11/virtualenv/rest_training/lib/python3.6/site-packages/pymysql/connections.py", line 732, in _read_query_result
    result.read()
  File "/home/alta11/virtualenv/rest_training/lib/python3.6/site-packages/pymysql/connections.py", line 1075, in read
    first_packet = self.connection._read_packet()
  File "/home/alta11/virtualenv/rest_training/lib/python3.6/site-packages/pymysql/connections.py", line 684, in _read_packet
    packet.check_error()
  File "/home/alta11/virtualenv/rest_training/lib/python3.6/site-packages/pymysql/protocol.py", line 220, in check_error
    err.raise_mysql_exception(self._data)
  File "/home/alta11/virtualenv/rest_training/lib/python3.6/site-packages/pymysql/err.py", line 109, in raise_mysql_exception
    raise errorclass(errno, errval)
sqlalchemy.exc.IntegrityError: (pymysql.err.IntegrityError) (1062, "Duplicate entry 'fast' for key 'name'")
[SQL: INSERT INTO user (name, age, sex, client_id, updated_at, deleted_at, password) VALUES (%(name)s, %(age)s, %(sex)s, %(client_id)s, %(updated_at)s, %(deleted_at)s, %(password)s)]
[parameters: {'name': 'fast', 'age': '20', 'sex': 'male', 'client_id': '1', 'updated_at': None, 'deleted_at': None, 'password': None}]
(Background on this error at: http://sqlalche.me/e/gkpj)
[2020-04-16 19:27:40,852] {/home/alta11/fullstack5_alul/Restful_API/2-FlaskRouting_Controller_Blueprint/blueprints/__init__.py:52} ERROR - REQUEST_LOG	{"status_code": 500, "method": "POST", "code": "500 INTERNAL SERVER ERROR", "uri": "/user?", "request": {"name": "fast", "age": 20, "sex": "male", "client_id": 1, "password": "alterraacademy"}, "response": {"message": "Internal Server Error"}}
[2020-04-16 19:27:56,876] {/home/alta11/fullstack5_alul/Restful_API/2-FlaskRouting_Controller_Blueprint/blueprints/__init__.py:42} WARNING - REQUEST_LOG	{"status_code": 200, "method": "POST", "code": "200 OK", "uri": "/user?", "request": {"name": "andre", "age": 20, "sex": "male", "client_id": 1, "password": "alterraacademy"}, "response": {"id": 9, "name": "andre", "age": 20, "sex": "male", "client_id": 1, "password": null}}
[2020-04-16 19:28:22,597] {/home/alta11/fullstack5_alul/Restful_API/2-FlaskRouting_Controller_Blueprint/blueprints/__init__.py:42} WARNING - REQUEST_LOG	{"status_code": 200, "method": "POST", "code": "200 OK", "uri": "/user?", "request": {"name": "andren", "age": 20, "sex": "male", "client_id": 1, "password": "alterraacademy"}, "response": {"id": 10, "name": "andren", "age": 20, "sex": "male", "client_id": 1, "password": null}}
